Workbook

Sheet Portfolios
B1: NP/DD and Total Trades are based on 2023.1.1-2025.5.30, this is to give a glance of strategy overall performance as well as trading frequency.
B2: Monthly Returns are based 3% Capital and 7 Leverage, to give a reference of recent performance and also a sizing choice
A3: KEY | B3: STATUS | C3: RATIO | D3: ID | E3: COIN PAIR | F3: STRATEGY | G3: TIMEFRAME | H3: Initial Mark | I3: Calculated Size | J3: Actual Size | K3: Avg PnL per trade | L3: NP/DD | M3: Total Trades | N3: INCUBATION | P3: SEP | Q3: AUG | R3: JULY | S3: JUNE | T3: MAY | U3: APR | V3: MAR | W3: FEB | X3: JAN | Y3: LINK
B4: BB/DexAlgo | C4: 5000 | D4: 7x | E4: 14000
A5: =D5&"|"&E5&"|"&F5&"|"&G5 -> [17ab2738]|ARB|stiff Surge|45m | B5: active | C5: =H5/$C$4 -> 1 | D5: [17ab2738] | E5: ARB | F5: stiff Surge | G5: 45m | H5: 5000 | I5: =H5*0.21 -> 1050 | J5: 1200 | K5: 27 | L5: {=IFERROR(INDEX('Strategy Watchlist'!L:L,MATCH($A5,'Strategy Watchlist'!$A:$A,0)),"Not Found")} -> 10.965644 | M5: {=IFERROR(INDEX('Strategy Watchlist'!M:M,MATCH($A5,'Strategy Watchlist'!$A:$A,0)),"Not Found")} -> 824 | N5: {=IFERROR(INDEX('Strategy Watchlist'!N:N,MATCH($A5,'Strategy Watchlist'!$A:$A,0)),"Not Found")} -> 45689 | O5: {=IFERROR(INDEX('Strategy Watchlist'!P:P,MATCH($A5,'Strategy Watchlist'!$A:$A,0)),"Not Found")} -> -1.7 | P5: {=IFERROR(INDEX('Strategy Watchlist'!Q:Q,MATCH($A5,'Strategy Watchlist'!$A:$A,0)),"Not Found")} -> -6.85 | Q5: {=IFERROR(INDEX('Strategy Watchlist'!R:R,MATCH($A5,'Strategy Watchlist'!$A:$A,0)),"Not Found")} -> 1.99 | R5: {=IFERROR(INDEX('Strategy Watchlist'!S:S,MATCH($A5,'Strategy Watchlist'!$A:$A,0)),"Not Found")} -> 6.96 | S5: {=IFERROR(INDEX('Strategy Watchlist'!T:T,MATCH($A5,'Strategy Watchlist'!$A:$A,0)),"Not Found")} -> 8.074 | T5: {=IFERROR(INDEX('Strategy Watchlist'!U:U,MATCH($A5,'Strategy Watchlist'!$A:$A,0)),"Not Found")} -> 11.5 | U5: {=IFERROR(INDEX('Strategy Watchlist'!V:V,MATCH($A5,'Strategy Watchlist'!$A:$A,0)),"Not Found")} -> 2.75 | V5: {=IFERROR(INDEX('Strategy Watchlist'!W:W,MATCH($A5,'Strategy Watchlist'!$A:$A,0)),"Not Found")} -> 2.57 | W5: {=IFERROR(INDEX('Strategy Watchlist'!X:X,MATCH($A5,'Strategy Watchlist'!$A:$A,0)),"Not Found")} -> 6.31 | X5: {=IFERROR(INDEX('Strategy Watchlist'!Y:Y,MATCH($A5,'Strategy Watchlist'!$A:$A,0)),"Not Found")} -> 7.91 | Y5: {=IFERROR(INDEX('Strategy Watchlist'!Z:Z,MATCH($A5,'Strategy Watchlist'!$A:$A,0)),"Not Found")} -> https://www.tradingview.com/chart/EjQUtmuc/
A6: =D6&"|"&E6&"|"&F6&"|"&G6 -> |DOGE|MACD|45m | B6: active | C6: =H6/$C$4 -> 0.4 | E6: DOGE | F6: MACD | G6: 45m | H6: 2000 | I6: =H6*0.21 -> 420 | J6: 800 | K6: 30 | L6: {=IFERROR(INDEX('Strategy Watchlist'!L:L,MATCH($A6,'Strategy Watchlist'!$A:$A,0)),"Not Found")} -> 6.8331771 | M6: {=IFERROR(INDEX('Strategy Watchlist'!M:M,MATCH($A6,'Strategy Watchlist'!$A:$A,0)),"Not Found")} -> 147 | N6: {=IFERROR(INDEX('Strategy Watchlist'!N:N,MATCH($A6,'Strategy Watchlist'!$A:$A,0)),"Not Found")} -> 45662 | O6: {=IFERROR(INDEX('Strategy Watchlist'!P:P,MATCH($A6,'Strategy Watchlist'!$A:$A,0)),"Not Found")} -> -3.88 | P6: {=IFERROR(INDEX('Strategy Watchlist'!Q:Q,MATCH($A6,'Strategy Watchlist'!$A:$A,0)),"Not Found")} -> 5.91 | Q6: {=IFERROR(INDEX('Strategy Watchlist'!R:R,MATCH($A6,'Strategy Watchlist'!$A:$A,0)),"Not Found")} -> -0.08 | R6: {=IFERROR(INDEX('Strategy Watchlist'!S:S,MATCH($A6,'Strategy Watchlist'!$A:$A,0)),"Not Found")} -> 4.72 | S6: {=IFERROR(INDEX('Strategy Watchlist'!T:T,MATCH($A6,'Strategy Watchlist'!$A:$A,0)),"Not Found")} -> 8.93 | T6: {=IFERROR(INDEX('Strategy Watchlist'!U:U,MATCH($A6,'Strategy Watchlist'!$A:$A,0)),"Not Found")} -> 2.69 | U6: {=IFERROR(INDEX('Strategy Watchlist'!V:V,MATCH($A6,'Strategy Watchlist'!$A:$A,0)),"Not Found")} -> 2.04 | V6: {=IFERROR(INDEX('Strategy Watchlist'!W:W,MATCH($A6,'Strategy Watchlist'!$A:$A,0)),"Not Found")} -> 5.31 | W6: {=IFERROR(INDEX('Strategy Watchlist'!X:X,MATCH($A6,'Strategy Watchlist'!$A:$A,0)),"Not Found")} -> 0.72 | X6: {=IFERROR(INDEX('Strategy Watchlist'!Y:Y,MATCH($A6,'Strategy Watchlist'!$A:$A,0)),"Not Found")} -> 3.27 | Y6: {=IFERROR(INDEX('Strategy Watchlist'!Z:Z,MATCH($A6,'Strategy Watchlist'!$A:$A,0)),"Not Found")} -> https://www.tradingview.com/chart/Dvd9vGt5/
A7: =D7&"|"&E7&"|"&F7&"|"&G7 -> [e92283ec]|HBAR|Heiken-Ashi|30m | B7: active | C7: =H7/$C$4 -> 0.6 | D7: [e92283ec] | E7: HBAR | F7: Heiken-Ashi | G7: 30m | H7: 3000 | I7: =H7*0.21 -> 630 | J7: 630 | K7: 30 | L7: {=IFERROR(INDEX('Strategy Watchlist'!L:L,MATCH($A7,'Strategy Watchlist'!$A:$A,0)),"Not Found")} -> 6.7744 | M7: {=IFERROR(INDEX('Strategy Watchlist'!M:M,MATCH($A7,'Strategy Watchlist'!$A:$A,0)),"Not Found")} -> 224 | N7: {=IFERROR(INDEX('Strategy Watchlist'!N:N,MATCH($A7,'Strategy Watchlist'!$A:$A,0)),"Not Found")} -> 45833 | O7: {=IFERROR(INDEX('Strategy Watchlist'!P:P,MATCH($A7,'Strategy Watchlist'!$A:$A,0)),"Not Found")} -> 1.01 | P7: {=IFERROR(INDEX('Strategy Watchlist'!Q:Q,MATCH($A7,'Strategy Watchlist'!$A:$A,0)),"Not Found")} -> -1.15 | Q7: {=IFERROR(INDEX('Strategy Watchlist'!R:R,MATCH($A7,'Strategy Watchlist'!$A:$A,0)),"Not Found")} -> 0.83 | R7: {=IFERROR(INDEX('Strategy Watchlist'!S:S,MATCH($A7,'Strategy Watchlist'!$A:$A,0)),"Not Found")} -> 1.52 | S7: {=IFERROR(INDEX('Strategy Watchlist'!T:T,MATCH($A7,'Strategy Watchlist'!$A:$A,0)),"Not Found")} -> -0.03 | T7: {=IFERROR(INDEX('Strategy Watchlist'!U:U,MATCH($A7,'Strategy Watchlist'!$A:$A,0)),"Not Found")} -> 4.38 | U7: {=IFERROR(INDEX('Strategy Watchlist'!V:V,MATCH($A7,'Strategy Watchlist'!$A:$A,0)),"Not Found")} -> 1.95 | V7: {=IFERROR(INDEX('Strategy Watchlist'!W:W,MATCH($A7,'Strategy Watchlist'!$A:$A,0)),"Not Found")} -> 1.98 | W7: {=IFERROR(INDEX('Strategy Watchlist'!X:X,MATCH($A7,'Strategy Watchlist'!$A:$A,0)),"Not Found")} -> 4.59 | X7: {=IFERROR(INDEX('Strategy Watchlist'!Y:Y,MATCH($A7,'Strategy Watchlist'!$A:$A,0)),"Not Found")} -> -1.3 | Y7: {=IFERROR(INDEX('Strategy Watchlist'!Z:Z,MATCH($A7,'Strategy Watchlist'!$A:$A,0)),"Not Found")} -> https://www.tradingview.com/chart/ygHXwF84/
A8: =D8&"|"&E8&"|"&F8&"|"&G8 -> [f80d2657]|PePe|JP Trend|30m | B8: active | C8: =H8/$C$4 -> 0.8 | D8: [f80d2657] | E8: PePe | F8: JP Trend | G8: 30m | H8: 4000 | I8: =H8*0.21 -> 840 | J8: 840 | K8: 30 | L8: {=IFERROR(INDEX('Strategy Watchlist'!L:L,MATCH($A8,'Strategy Watchlist'!$A:$A,0)),"Not Found")} -> 11.341646 | M8: {=IFERROR(INDEX('Strategy Watchlist'!M:M,MATCH($A8,'Strategy Watchlist'!$A:$A,0)),"Not Found")} -> 302 | N8: {=IFERROR(INDEX('Strategy Watchlist'!N:N,MATCH($A8,'Strategy Watchlist'!$A:$A,0)),"Not Found")} -> 45662 | O8: {=IFERROR(INDEX('Strategy Watchlist'!P:P,MATCH($A8,'Strategy Watchlist'!$A:$A,0)),"Not Found")} -> 3.05 | P8: {=IFERROR(INDEX('Strategy Watchlist'!Q:Q,MATCH($A8,'Strategy Watchlist'!$A:$A,0)),"Not Found")} -> 1.52 | Q8: {=IFERROR(INDEX('Strategy Watchlist'!R:R,MATCH($A8,'Strategy Watchlist'!$A:$A,0)),"Not Found")} -> -3.15 | R8: {=IFERROR(INDEX('Strategy Watchlist'!S:S,MATCH($A8,'Strategy Watchlist'!$A:$A,0)),"Not Found")} -> 2.3 | S8: {=IFERROR(INDEX('Strategy Watchlist'!T:T,MATCH($A8,'Strategy Watchlist'!$A:$A,0)),"Not Found")} -> -0.12 | T8: {=IFERROR(INDEX('Strategy Watchlist'!U:U,MATCH($A8,'Strategy Watchlist'!$A:$A,0)),"Not Found")} -> 5.69 | U8: {=IFERROR(INDEX('Strategy Watchlist'!V:V,MATCH($A8,'Strategy Watchlist'!$A:$A,0)),"Not Found")} -> -1.33 | V8: {=IFERROR(INDEX('Strategy Watchlist'!W:W,MATCH($A8,'Strategy Watchlist'!$A:$A,0)),"Not Found")} -> 2.12 | W8: {=IFERROR(INDEX('Strategy Watchlist'!X:X,MATCH($A8,'Strategy Watchlist'!$A:$A,0)),"Not Found")} -> 3.07 | X8: {=IFERROR(INDEX('Strategy Watchlist'!Y:Y,MATCH($A8,'Strategy Watchlist'!$A:$A,0)),"Not Found")} -> 3.75 | Y8: {=IFERROR(INDEX('Strategy Watchlist'!Z:Z,MATCH($A8,'Strategy Watchlist'!$A:$A,0)),"Not Found")} -> https://www.tradingview.com/chart/uNPZ2spK/
A9: =D9&"|"&E9&"|"&F9&"|"&G9 -> [0c4624b7]|SOL|volVangard|30m | B9: active | C9: =H9/$C$4 -> 0.8 | D9: [0c4624b7] | E9: SOL | F9: volVangard | G9: 30m | H9: 4000 | I9: =H9*0.21 -> 840 | J9: =I9 -> 840 | K9: 47 | L9: {=IFERROR(INDEX('Strategy Watchlist'!L:L,MATCH($A9,'Strategy Watchlist'!$A:$A,0)),"Not Found")} -> 9.5332198 | M9: {=IFERROR(INDEX('Strategy Watchlist'!M:M,MATCH($A9,'Strategy Watchlist'!$A:$A,0)),"Not Found")} -> 118 | N9: {=IFERROR(INDEX('Strategy Watchlist'!N:N,MATCH($A9,'Strategy Watchlist'!$A:$A,0)),"Not Found")} -> 45772 | O9: {=IFERROR(INDEX('Strategy Watchlist'!P:P,MATCH($A9,'Strategy Watchlist'!$A:$A,0)),"Not Found")} -> -0.99 | P9: {=IFERROR(INDEX('Strategy Watchlist'!Q:Q,MATCH($A9,'Strategy Watchlist'!$A:$A,0)),"Not Found")} -> 4.09 | Q9: {=IFERROR(INDEX('Strategy Watchlist'!R:R,MATCH($A9,'Strategy Watchlist'!$A:$A,0)),"Not Found")} -> 0.37 | R9: {=IFERROR(INDEX('Strategy Watchlist'!S:S,MATCH($A9,'Strategy Watchlist'!$A:$A,0)),"Not Found")} -> -3.58 | S9: {=IFERROR(INDEX('Strategy Watchlist'!T:T,MATCH($A9,'Strategy Watchlist'!$A:$A,0)),"Not Found")} -> 6.51 | T9: {=IFERROR(INDEX('Strategy Watchlist'!U:U,MATCH($A9,'Strategy Watchlist'!$A:$A,0)),"Not Found")} -> -0.43 | U9: {=IFERROR(INDEX('Strategy Watchlist'!V:V,MATCH($A9,'Strategy Watchlist'!$A:$A,0)),"Not Found")} -> 5.78 | V9: {=IFERROR(INDEX('Strategy Watchlist'!W:W,MATCH($A9,'Strategy Watchlist'!$A:$A,0)),"Not Found")} -> -0.64 | W9: {=IFERROR(INDEX('Strategy Watchlist'!X:X,MATCH($A9,'Strategy Watchlist'!$A:$A,0)),"Not Found")} -> 1.32 | X9: {=IFERROR(INDEX('Strategy Watchlist'!Y:Y,MATCH($A9,'Strategy Watchlist'!$A:$A,0)),"Not Found")} -> 0.33 | Y9: {=IFERROR(INDEX('Strategy Watchlist'!Z:Z,MATCH($A9,'Strategy Watchlist'!$A:$A,0)),"Not Found")} -> https://www.tradingview.com/chart/tJDJVri5/
A10: =D10&"|"&E10&"|"&F10&"|"&G10 -> [a9aeb4cc]|ETH|McGinley|90m | B10: active | C10: =H10/$C$4 -> 0.8 | D10: [a9aeb4cc] | E10: ETH | F10: McGinley | G10: 90m | H10: 4000 | I10: =H10*0.21 -> 840 | J10: =I10 -> 840 | K10: 24 | L10: {=IFERROR(INDEX('Strategy Watchlist'!L:L,MATCH($A10,'Strategy Watchlist'!$A:$A,0)),"Not Found")} -> 7.4173228 | M10: {=IFERROR(INDEX('Strategy Watchlist'!M:M,MATCH($A10,'Strategy Watchlist'!$A:$A,0)),"Not Found")} -> 72 | N10: {=IFERROR(INDEX('Strategy Watchlist'!N:N,MATCH($A10,'Strategy Watchlist'!$A:$A,0)),"Not Found")} -> 45772 | O10: {=IFERROR(INDEX('Strategy Watchlist'!P:P,MATCH($A10,'Strategy Watchlist'!$A:$A,0)),"Not Found")} -> -0.43 | P10: {=IFERROR(INDEX('Strategy Watchlist'!Q:Q,MATCH($A10,'Strategy Watchlist'!$A:$A,0)),"Not Found")} -> -0.39 | Q10: {=IFERROR(INDEX('Strategy Watchlist'!R:R,MATCH($A10,'Strategy Watchlist'!$A:$A,0)),"Not Found")} -> 2.45 | R10: {=IFERROR(INDEX('Strategy Watchlist'!S:S,MATCH($A10,'Strategy Watchlist'!$A:$A,0)),"Not Found")} -> -0.24 | S10: {=IFERROR(INDEX('Strategy Watchlist'!T:T,MATCH($A10,'Strategy Watchlist'!$A:$A,0)),"Not Found")} -> 0.53 | T10: {=IFERROR(INDEX('Strategy Watchlist'!U:U,MATCH($A10,'Strategy Watchlist'!$A:$A,0)),"Not Found")} -> 2.38 | U10: {=IFERROR(INDEX('Strategy Watchlist'!V:V,MATCH($A10,'Strategy Watchlist'!$A:$A,0)),"Not Found")} -> 0.94 | V10: {=IFERROR(INDEX('Strategy Watchlist'!W:W,MATCH($A10,'Strategy Watchlist'!$A:$A,0)),"Not Found")} -> 0 | W10: {=IFERROR(INDEX('Strategy Watchlist'!X:X,MATCH($A10,'Strategy Watchlist'!$A:$A,0)),"Not Found")} -> 2.77 | X10: {=IFERROR(INDEX('Strategy Watchlist'!Y:Y,MATCH($A10,'Strategy Watchlist'!$A:$A,0)),"Not Found")} -> -0.13 | Y10: {=IFERROR(INDEX('Strategy Watchlist'!Z:Z,MATCH($A10,'Strategy Watchlist'!$A:$A,0)),"Not Found")} -> https://www.tradingview.com/chart/dPRT8fSK/
A11: =D11&"|"&E11&"|"&F11&"|"&G11 -> [65caeaa0]|ROSE|WolfnBear|1H | B11: active | C11: =H11/$C$4 -> 0.8 | D11: [65caeaa0] | E11: ROSE | F11: WolfnBear | G11: 1H | H11: 4000 | I11: =H11*0.21 -> 840 | J11: =I11 -> 840 | K11: 22 | L11: {=IFERROR(INDEX('Strategy Watchlist'!L:L,MATCH($A11,'Strategy Watchlist'!$A:$A,0)),"Not Found")} -> 9.1257485 | M11: {=IFERROR(INDEX('Strategy Watchlist'!M:M,MATCH($A11,'Strategy Watchlist'!$A:$A,0)),"Not Found")} -> 172 | N11: {=IFERROR(INDEX('Strategy Watchlist'!N:N,MATCH($A11,'Strategy Watchlist'!$A:$A,0)),"Not Found")} -> 45682 | O11: {=IFERROR(INDEX('Strategy Watchlist'!P:P,MATCH($A11,'Strategy Watchlist'!$A:$A,0)),"Not Found")} -> 1.04 | P11: {=IFERROR(INDEX('Strategy Watchlist'!Q:Q,MATCH($A11,'Strategy Watchlist'!$A:$A,0)),"Not Found")} -> 2.39 | Q11: {=IFERROR(INDEX('Strategy Watchlist'!R:R,MATCH($A11,'Strategy Watchlist'!$A:$A,0)),"Not Found")} -> 0.38 | R11: {=IFERROR(INDEX('Strategy Watchlist'!S:S,MATCH($A11,'Strategy Watchlist'!$A:$A,0)),"Not Found")} -> 1.76 | S11: {=IFERROR(INDEX('Strategy Watchlist'!T:T,MATCH($A11,'Strategy Watchlist'!$A:$A,0)),"Not Found")} -> 0.72 | T11: {=IFERROR(INDEX('Strategy Watchlist'!U:U,MATCH($A11,'Strategy Watchlist'!$A:$A,0)),"Not Found")} -> -0.84 | U11: {=IFERROR(INDEX('Strategy Watchlist'!V:V,MATCH($A11,'Strategy Watchlist'!$A:$A,0)),"Not Found")} -> -0.24 | V11: {=IFERROR(INDEX('Strategy Watchlist'!W:W,MATCH($A11,'Strategy Watchlist'!$A:$A,0)),"Not Found")} -> -1.19 | W11: {=IFERROR(INDEX('Strategy Watchlist'!X:X,MATCH($A11,'Strategy Watchlist'!$A:$A,0)),"Not Found")} -> 0.18 | X11: {=IFERROR(INDEX('Strategy Watchlist'!Y:Y,MATCH($A11,'Strategy Watchlist'!$A:$A,0)),"Not Found")} -> 2.34 | Y11: {=IFERROR(INDEX('Strategy Watchlist'!Z:Z,MATCH($A11,'Strategy Watchlist'!$A:$A,0)),"Not Found")} -> https://www.tradingview.com/chart/p2Bvj1LX/
A12: =D12&"|"&E12&"|"&F12&"|"&G12 -> |APE|precisionTrend|30m | B12: active | C12: =H12/$C$4 -> 0.6 | E12: APE | F12: precisionTrend | G12: 30m | H12: 3000 | I12: =H12*0.21 -> 630 | J12: =I12 -> 630 | K12: 23 | L12: {=IFERROR(INDEX('Strategy Watchlist'!L:L,MATCH($A12,'Strategy Watchlist'!$A:$A,0)),"Not Found")} -> 4.1660424 | M12: {=IFERROR(INDEX('Strategy Watchlist'!M:M,MATCH($A12,'Strategy Watchlist'!$A:$A,0)),"Not Found")} -> 278 | N12: {=IFERROR(INDEX('Strategy Watchlist'!N:N,MATCH($A12,'Strategy Watchlist'!$A:$A,0)),"Not Found")} -> 45778 | O12: {=IFERROR(INDEX('Strategy Watchlist'!P:P,MATCH($A12,'Strategy Watchlist'!$A:$A,0)),"Not Found")} -> -0.99 | P12: {=IFERROR(INDEX('Strategy Watchlist'!Q:Q,MATCH($A12,'Strategy Watchlist'!$A:$A,0)),"Not Found")} -> 3 | Q12: {=IFERROR(INDEX('Strategy Watchlist'!R:R,MATCH($A12,'Strategy Watchlist'!$A:$A,0)),"Not Found")} -> 1.66 | R12: {=IFERROR(INDEX('Strategy Watchlist'!S:S,MATCH($A12,'Strategy Watchlist'!$A:$A,0)),"Not Found")} -> -2.79 | S12: {=IFERROR(INDEX('Strategy Watchlist'!T:T,MATCH($A12,'Strategy Watchlist'!$A:$A,0)),"Not Found")} -> 0.63 | T12: {=IFERROR(INDEX('Strategy Watchlist'!U:U,MATCH($A12,'Strategy Watchlist'!$A:$A,0)),"Not Found")} -> 6.17 | U12: {=IFERROR(INDEX('Strategy Watchlist'!V:V,MATCH($A12,'Strategy Watchlist'!$A:$A,0)),"Not Found")} -> 3.56 | V12: {=IFERROR(INDEX('Strategy Watchlist'!W:W,MATCH($A12,'Strategy Watchlist'!$A:$A,0)),"Not Found")} -> 0.87 | W12: {=IFERROR(INDEX('Strategy Watchlist'!X:X,MATCH($A12,'Strategy Watchlist'!$A:$A,0)),"Not Found")} -> 1.73 | X12: {=IFERROR(INDEX('Strategy Watchlist'!Y:Y,MATCH($A12,'Strategy Watchlist'!$A:$A,0)),"Not Found")} -> 3.54 | Y12: {=IFERROR(INDEX('Strategy Watchlist'!Z:Z,MATCH($A12,'Strategy Watchlist'!$A:$A,0)),"Not Found")} -> https://www.tradingview.com/chart/oDhEAePi/
A13: =D13&"|"&E13&"|"&F13&"|"&G13 -> [fa32aee4]|LINK|McGinley|45m | B13: active | C13: =H13/$C$4 -> 0.4 | D13: [fa32aee4] | E13: LINK | F13: McGinley | G13: 45m | H13: 2000 | I13: =H13*0.21 -> 420 | J13: 520 | K13: 30 | L13: {=IFERROR(INDEX('Strategy Watchlist'!L:L,MATCH($A13,'Strategy Watchlist'!$A:$A,0)),"Not Found")} -> 16.683761 | M13: {=IFERROR(INDEX('Strategy Watchlist'!M:M,MATCH($A13,'Strategy Watchlist'!$A:$A,0)),"Not Found")} -> 176 | N13: {=IFERROR(INDEX('Strategy Watchlist'!N:N,MATCH($A13,'Strategy Watchlist'!$A:$A,0)),"Not Found")} -> 45833 | O13: {=IFERROR(INDEX('Strategy Watchlist'!P:P,MATCH($A13,'Strategy Watchlist'!$A:$A,0)),"Not Found")} -> -2.02 | P13: {=IFERROR(INDEX('Strategy Watchlist'!Q:Q,MATCH($A13,'Strategy Watchlist'!$A:$A,0)),"Not Found")} -> 0.36 | Q13: {=IFERROR(INDEX('Strategy Watchlist'!R:R,MATCH($A13,'Strategy Watchlist'!$A:$A,0)),"Not Found")} -> 7 | R13: {=IFERROR(INDEX('Strategy Watchlist'!S:S,MATCH($A13,'Strategy Watchlist'!$A:$A,0)),"Not Found")} -> 3.76 | S13: {=IFERROR(INDEX('Strategy Watchlist'!T:T,MATCH($A13,'Strategy Watchlist'!$A:$A,0)),"Not Found")} -> 2.22 | T13: {=IFERROR(INDEX('Strategy Watchlist'!U:U,MATCH($A13,'Strategy Watchlist'!$A:$A,0)),"Not Found")} -> 6.68 | U13: {=IFERROR(INDEX('Strategy Watchlist'!V:V,MATCH($A13,'Strategy Watchlist'!$A:$A,0)),"Not Found")} -> -0.14 | V13: {=IFERROR(INDEX('Strategy Watchlist'!W:W,MATCH($A13,'Strategy Watchlist'!$A:$A,0)),"Not Found")} -> 5.22 | W13: {=IFERROR(INDEX('Strategy Watchlist'!X:X,MATCH($A13,'Strategy Watchlist'!$A:$A,0)),"Not Found")} -> 0 | X13: {=IFERROR(INDEX('Strategy Watchlist'!Y:Y,MATCH($A13,'Strategy Watchlist'!$A:$A,0)),"Not Found")} -> 0.13 | Y13: {=IFERROR(INDEX('Strategy Watchlist'!Z:Z,MATCH($A13,'Strategy Watchlist'!$A:$A,0)),"Not Found")} -> https://www.tradingview.com/chart/CTC73Olh/
A14: =D14&"|"&E14&"|"&F14&"|"&G14 -> [3111f1fd]|NEAR|Stiff Surge|1H | B14: active | C14: =H14/$C$4 -> 0.4 | D14: [3111f1fd] | E14: NEAR | F14: Stiff Surge | G14: 1H | H14: 2000 | I14: 420 | J14: =I14 -> 420 | K14: 22 | L14: {=IFERROR(INDEX('Strategy Watchlist'!L:L,MATCH($A14,'Strategy Watchlist'!$A:$A,0)),"Not Found")} -> 3.1660517 | M14: {=IFERROR(INDEX('Strategy Watchlist'!M:M,MATCH($A14,'Strategy Watchlist'!$A:$A,0)),"Not Found")} -> 237 | N14: {=IFERROR(INDEX('Strategy Watchlist'!N:N,MATCH($A14,'Strategy Watchlist'!$A:$A,0)),"Not Found")} -> 45717 | O14: {=IFERROR(INDEX('Strategy Watchlist'!P:P,MATCH($A14,'Strategy Watchlist'!$A:$A,0)),"Not Found")} -> -1.39 | P14: {=IFERROR(INDEX('Strategy Watchlist'!Q:Q,MATCH($A14,'Strategy Watchlist'!$A:$A,0)),"Not Found")} -> 0.56 | Q14: {=IFERROR(INDEX('Strategy Watchlist'!R:R,MATCH($A14,'Strategy Watchlist'!$A:$A,0)),"Not Found")} -> -0.43 | R14: {=IFERROR(INDEX('Strategy Watchlist'!S:S,MATCH($A14,'Strategy Watchlist'!$A:$A,0)),"Not Found")} -> -0.45 | S14: {=IFERROR(INDEX('Strategy Watchlist'!T:T,MATCH($A14,'Strategy Watchlist'!$A:$A,0)),"Not Found")} -> 4.99 | T14: {=IFERROR(INDEX('Strategy Watchlist'!U:U,MATCH($A14,'Strategy Watchlist'!$A:$A,0)),"Not Found")} -> 4.37 | U14: {=IFERROR(INDEX('Strategy Watchlist'!V:V,MATCH($A14,'Strategy Watchlist'!$A:$A,0)),"Not Found")} -> -1.47 | V14: {=IFERROR(INDEX('Strategy Watchlist'!W:W,MATCH($A14,'Strategy Watchlist'!$A:$A,0)),"Not Found")} -> 1.85 | W14: {=IFERROR(INDEX('Strategy Watchlist'!X:X,MATCH($A14,'Strategy Watchlist'!$A:$A,0)),"Not Found")} -> -0.11 | X14: {=IFERROR(INDEX('Strategy Watchlist'!Y:Y,MATCH($A14,'Strategy Watchlist'!$A:$A,0)),"Not Found")} -> 1.53 | Y14: {=IFERROR(INDEX('Strategy Watchlist'!Z:Z,MATCH($A14,'Strategy Watchlist'!$A:$A,0)),"Not Found")} -> https://www.tradingview.com/chart/Q9MeKvVC/
A15: =D15&"|"&E15&"|"&F15&"|"&G15 -> [f2b236fa]|OP|glitchTrend|1H | B15: active | C15: =H15/$C$4 -> 0.4 | D15: [f2b236fa] | E15: OP | F15: glitchTrend | G15: 1H | H15: 2000 | I15: =H15*0.21 -> 420 | J15: =I15 -> 420 | K15: 25 | L15: =57.27/6.84 -> 8.372807 | M15: 409 | N15: 45863 | O15: {=IFERROR(INDEX('Strategy Watchlist'!P:P,MATCH($A15,'Strategy Watchlist'!$A:$A,0)),"Not Found")} -> 2.64 | P15: {=IFERROR(INDEX('Strategy Watchlist'!Q:Q,MATCH($A15,'Strategy Watchlist'!$A:$A,0)),"Not Found")} -> 0.13 | Q15: {=IFERROR(INDEX('Strategy Watchlist'!R:R,MATCH($A15,'Strategy Watchlist'!$A:$A,0)),"Not Found")} -> 1.69 | R15: {=IFERROR(INDEX('Strategy Watchlist'!S:S,MATCH($A15,'Strategy Watchlist'!$A:$A,0)),"Not Found")} -> 6.07 | S15: {=IFERROR(INDEX('Strategy Watchlist'!T:T,MATCH($A15,'Strategy Watchlist'!$A:$A,0)),"Not Found")} -> -3.19 | T15: {=IFERROR(INDEX('Strategy Watchlist'!U:U,MATCH($A15,'Strategy Watchlist'!$A:$A,0)),"Not Found")} -> 5.27 | U15: {=IFERROR(INDEX('Strategy Watchlist'!V:V,MATCH($A15,'Strategy Watchlist'!$A:$A,0)),"Not Found")} -> 3.43 | V15: {=IFERROR(INDEX('Strategy Watchlist'!W:W,MATCH($A15,'Strategy Watchlist'!$A:$A,0)),"Not Found")} -> 2.02 | W15: {=IFERROR(INDEX('Strategy Watchlist'!X:X,MATCH($A15,'Strategy Watchlist'!$A:$A,0)),"Not Found")} -> 0.08 | X15: {=IFERROR(INDEX('Strategy Watchlist'!Y:Y,MATCH($A15,'Strategy Watchlist'!$A:$A,0)),"Not Found")} -> 7.85 | Y15: {=IFERROR(INDEX('Strategy Watchlist'!Z:Z,MATCH($A15,'Strategy Watchlist'!$A:$A,0)),"Not Found")} -> https://www.tradingview.com/chart/IMFhBZl2/ | AU15: =AX15&"|"&AY15&"|"&AZ15&"|"&BA15 -> [f2b236fa]|OP|glitchTrend|1H | AV15: toWatch | AX15: [f2b236fa] | AY15: OP | AZ15: glitchTrend | BA15: 1H | BF15: =57.27/6.84 -> 8.372807 | BG15: 409 | BH15: 45863 | BI15: 0.5 | BJ15: 0.13 | BK15: 1.69 | BL15: 6.07 | BM15: -3.19 | BN15: 5.27 | BO15: 3.43 | BP15: 2.02 | BQ15: 0.08 | BR15: 7.85 | BS15: https://daviddtech.com/strategy/hongfei_xx-glitchytrend-opusdt-1h-22-07-2025-copy/
A18: =D18&"|"&E18&"|"&F18&"|"&G18 -> 5x|4400|| | B18: DexAglo 2 | D18: 5x | E18: 4400
A19: =D19&"|"&E19&"|"&F19&"|"&G19 -> [0436a8e8]|SOL|Trendhoo|90m | B19: active | C19: =H19/$C$4 -> 0.8 | D19: [0436a8e8] | E19: SOL | F19: Trendhoo | G19: 90m | H19: 4000 | I19: =H19*0.21 -> 840 | J19: =I19 -> 840 | K19: 22 | L19: {=IFERROR(INDEX('Strategy Watchlist'!L:L,MATCH($A19,'Strategy Watchlist'!$A:$A,0)),"Not Found")} -> 5.0460048 | M19: {=IFERROR(INDEX('Strategy Watchlist'!M:M,MATCH($A19,'Strategy Watchlist'!$A:$A,0)),"Not Found")} -> 327 | N19: {=IFERROR(INDEX('Strategy Watchlist'!N:N,MATCH($A19,'Strategy Watchlist'!$A:$A,0)),"Not Found")} -> 45863 | O19: {=IFERROR(INDEX('Strategy Watchlist'!P:P,MATCH($A19,'Strategy Watchlist'!$A:$A,0)),"Not Found")} -> -0.58 | P19: {=IFERROR(INDEX('Strategy Watchlist'!Q:Q,MATCH($A19,'Strategy Watchlist'!$A:$A,0)),"Not Found")} -> 2.3 | Q19: {=IFERROR(INDEX('Strategy Watchlist'!R:R,MATCH($A19,'Strategy Watchlist'!$A:$A,0)),"Not Found")} -> 0.88 | R19: {=IFERROR(INDEX('Strategy Watchlist'!S:S,MATCH($A19,'Strategy Watchlist'!$A:$A,0)),"Not Found")} -> 0.88 | S19: {=IFERROR(INDEX('Strategy Watchlist'!T:T,MATCH($A19,'Strategy Watchlist'!$A:$A,0)),"Not Found")} -> -0.19 | T19: {=IFERROR(INDEX('Strategy Watchlist'!U:U,MATCH($A19,'Strategy Watchlist'!$A:$A,0)),"Not Found")} -> -0.1 | U19: {=IFERROR(INDEX('Strategy Watchlist'!V:V,MATCH($A19,'Strategy Watchlist'!$A:$A,0)),"Not Found")} -> -0.52 | V19: {=IFERROR(INDEX('Strategy Watchlist'!W:W,MATCH($A19,'Strategy Watchlist'!$A:$A,0)),"Not Found")} -> 1.11 | W19: {=IFERROR(INDEX('Strategy Watchlist'!X:X,MATCH($A19,'Strategy Watchlist'!$A:$A,0)),"Not Found")} -> 2.02 | X19: {=IFERROR(INDEX('Strategy Watchlist'!Y:Y,MATCH($A19,'Strategy Watchlist'!$A:$A,0)),"Not Found")} -> 2.73 | Y19: https://daviddtech.com/strategy/borawx-trendhoov5-solusdt-90m-30-07-copy/ | AU19: =AX19&"|"&AY19&"|"&AZ19&"|"&BA19 -> [0436a8e8]|SOL|Trendhoo|90m | AV19: active | AW19: 0.2 | AX19: [0436a8e8] | AY19: SOL | AZ19: Trendhoo | BA19: 90m | BF19: =20.84/4.13 -> 5.0460048 | BG19: 327 | BH19: 45863 | BI19: 0.72 | BJ19: 1.94 | BK19: 0.74 | BL19: 0.74 | BM19: -0.19 | BN19: -0.1 | BO19: -0.52 | BP19: 1.11 | BQ19: 2.02 | BR19: 2.73 | BS19: https://daviddtech.com/strategy/borawx-trendhoov5-solusdt-90m-30-07-copy/
A20: =D20&"|"&E20&"|"&F20&"|"&G20 -> [1adc9501]|ETH|DeadZone|1H | B20: active | C20: =H20/$C$4 -> 0.6 | D20: [1adc9501] | E20: ETH | F20: DeadZone | G20: 1H | H20: 3000 | I20: =H20*0.21 -> 630 | J20: =I20 -> 630 | K20: 22 | L20: {=IFERROR(INDEX('Strategy Watchlist'!L:L,MATCH($A20,'Strategy Watchlist'!$A:$A,0)),"Not Found")} -> 8.4111675 | M20: {=IFERROR(INDEX('Strategy Watchlist'!M:M,MATCH($A20,'Strategy Watchlist'!$A:$A,0)),"Not Found")} -> 134 | N20: {=IFERROR(INDEX('Strategy Watchlist'!N:N,MATCH($A20,'Strategy Watchlist'!$A:$A,0)),"Not Found")} -> 45802 | O20: {=IFERROR(INDEX('Strategy Watchlist'!P:P,MATCH($A20,'Strategy Watchlist'!$A:$A,0)),"Not Found")} -> 0.51 | P20: {=IFERROR(INDEX('Strategy Watchlist'!Q:Q,MATCH($A20,'Strategy Watchlist'!$A:$A,0)),"Not Found")} -> 0.63 | Q20: {=IFERROR(INDEX('Strategy Watchlist'!R:R,MATCH($A20,'Strategy Watchlist'!$A:$A,0)),"Not Found")} -> 4.53 | R20: {=IFERROR(INDEX('Strategy Watchlist'!S:S,MATCH($A20,'Strategy Watchlist'!$A:$A,0)),"Not Found")} -> 3.6 | S20: {=IFERROR(INDEX('Strategy Watchlist'!T:T,MATCH($A20,'Strategy Watchlist'!$A:$A,0)),"Not Found")} -> 1.09 | T20: {=IFERROR(INDEX('Strategy Watchlist'!U:U,MATCH($A20,'Strategy Watchlist'!$A:$A,0)),"Not Found")} -> 2.31 | U20: {=IFERROR(INDEX('Strategy Watchlist'!V:V,MATCH($A20,'Strategy Watchlist'!$A:$A,0)),"Not Found")} -> 0.49 | V20: {=IFERROR(INDEX('Strategy Watchlist'!W:W,MATCH($A20,'Strategy Watchlist'!$A:$A,0)),"Not Found")} -> -1.63 | W20: {=IFERROR(INDEX('Strategy Watchlist'!X:X,MATCH($A20,'Strategy Watchlist'!$A:$A,0)),"Not Found")} -> 0.27 | X20: {=IFERROR(INDEX('Strategy Watchlist'!Y:Y,MATCH($A20,'Strategy Watchlist'!$A:$A,0)),"Not Found")} -> 2.35 | Y20: https://daviddtech.com/strategy/borawx-trendhoov5-solusdt-90m-30-07-copy/ | AU20: =AX20&"|"&AY20&"|"&AZ20&"|"&BA20 -> [1adc9501]|ETH|DeadZone|1H | AV20: toWatch | AX20: [1adc9501] | AY20: ETH | AZ20: DeadZone | BA20: 1H | BF20: =33.14/3.94 -> 8.4111675 | BG20: 134 | BH20: 45802 | BI20: 0.9 | BJ20: 0.63 | BK20: 4.53 | BL20: 3.6 | BM20: 1.09 | BN20: 2.31 | BO20: 0.49 | BP20: -1.63 | BQ20: 0.27 | BR20: 2.35 | BS20: https://daviddtech.com/strategy/eth_deadzone_1hr-copy-croc5455/
A21: =D21&"|"&E21&"|"&F21&"|"&G21 -> [04ea3071]|BTC|AI vs Ninja Turtle|76min | B21: active | C21: =H21/$C$4 -> 0.6 | D21: [04ea3071] | E21: BTC | F21: AI vs Ninja Turtle | G21: 76min | H21: 3000 | I21: =H21*0.21 -> 630 | J21: 1000 | K21: 40 | L21: =37.21/4.33 -> 8.5935335 | M21: 78 | N21: 45682 | O21: {=IFERROR(INDEX('Strategy Watchlist'!P:P,MATCH($A21,'Strategy Watchlist'!$A:$A,0)),"Not Found")} -> 1.67 | P21: 0.99 | Q21: -0.22 | R21: 2.83 | S21: -1.36 | T21: 3.58 | U21: -0.43 | V21: 1.13 | W21: 1.58 | X21: 3.31 | Y21: https://daviddtech.com/strategy/igorek-aivsnn-btcusdt-76m-22-10-2024-copy/ | AU21: =AX21&"|"&AY21&"|"&AZ21&"|"&BA21 -> [04ea3071]|BTC|AI vs Ninja Turtle|76min | AV21: active | AX21: [04ea3071] | AY21: BTC | AZ21: AI vs Ninja Turtle | BA21: 76min | BF21: =37.21/4.33 -> 8.5935335 | BG21: 78 | BH21: 45682 | BI21: 0.99 | BJ21: -0.22 | BK21: 2.83 | BL21: -1.36 | BM21: 3.58 | BN21: -0.43 | BO21: 1.13 | BP21: 1.58 | BQ21: 3.31 | BR21: https://daviddtech.com/strategy/igorek-aivsnn-btcusdt-76m-22-10-2024-copy/
A22: =D22&"|"&E22&"|"&F22&"|"&G22 -> [967f469a]|LINK|McGingley|45m | B22: paused | C22: =H22/$C$4 -> 0.6 | D22: [967f469a] | E22: LINK | F22: McGingley | G22: 45m | H22: 3000 | I22: =H22*0.21 -> 630 | J22: 5680 | K22: 22 | L22: {=IFERROR(INDEX('Strategy Watchlist'!L:L,MATCH($A22,'Strategy Watchlist'!$A:$A,0)),"Not Found")} -> 20.013514 | M22: {=IFERROR(INDEX('Strategy Watchlist'!M:M,MATCH($A22,'Strategy Watchlist'!$A:$A,0)),"Not Found")} -> 83 | N22: {=IFERROR(INDEX('Strategy Watchlist'!N:N,MATCH($A22,'Strategy Watchlist'!$A:$A,0)),"Not Found")} -> 45717 | O22: {=IFERROR(INDEX('Strategy Watchlist'!P:P,MATCH($A22,'Strategy Watchlist'!$A:$A,0)),"Not Found")} -> -1.22 | P22: {=IFERROR(INDEX('Strategy Watchlist'!Q:Q,MATCH($A22,'Strategy Watchlist'!$A:$A,0)),"Not Found")} -> 0.61 | Q22: {=IFERROR(INDEX('Strategy Watchlist'!R:R,MATCH($A22,'Strategy Watchlist'!$A:$A,0)),"Not Found")} -> 1.39 | R22: {=IFERROR(INDEX('Strategy Watchlist'!S:S,MATCH($A22,'Strategy Watchlist'!$A:$A,0)),"Not Found")} -> 0.12 | S22: {=IFERROR(INDEX('Strategy Watchlist'!T:T,MATCH($A22,'Strategy Watchlist'!$A:$A,0)),"Not Found")} -> 1.48 | T22: {=IFERROR(INDEX('Strategy Watchlist'!U:U,MATCH($A22,'Strategy Watchlist'!$A:$A,0)),"Not Found")} -> 0.54 | U22: {=IFERROR(INDEX('Strategy Watchlist'!V:V,MATCH($A22,'Strategy Watchlist'!$A:$A,0)),"Not Found")} -> 0.91 | V22: {=IFERROR(INDEX('Strategy Watchlist'!W:W,MATCH($A22,'Strategy Watchlist'!$A:$A,0)),"Not Found")} -> 0.02 | W22: {=IFERROR(INDEX('Strategy Watchlist'!X:X,MATCH($A22,'Strategy Watchlist'!$A:$A,0)),"Not Found")} -> 0.97 | X22: {=IFERROR(INDEX('Strategy Watchlist'!Y:Y,MATCH($A22,'Strategy Watchlist'!$A:$A,0)),"Not Found")} -> -0.53 | Y22: {=IFERROR(INDEX('Strategy Watchlist'!Z:Z,MATCH($A22,'Strategy Watchlist'!$A:$A,0)),"Not Found")} -> https://www.tradingview.com/chart/285fzTJB/
A24: =D24&"|"&E24&"|"&F24&"|"&G24 -> 7x|4400|| | B24: DexAlgo 3 | D24: 7x | E24: 4400
A25: =D25&"|"&E25&"|"&F25&"|"&G25 -> 17.12.2024|ARB|Heiken-Ashi|45m | B25: active | C25: =H25/$C$4 -> 0.4 | D25: 17.12.2024 | E25: ARB | F25: Heiken-Ashi | G25: 45m | H25: 2000 | I25: =H25*0.21 -> 420 | J25: 440 | K25: 16 | L25: {=IFERROR(INDEX('Strategy Watchlist'!L:L,MATCH($A25,'Strategy Watchlist'!$A:$A,0)),"Not Found")} -> 12.102857 | M25: {=IFERROR(INDEX('Strategy Watchlist'!M:M,MATCH($A25,'Strategy Watchlist'!$A:$A,0)),"Not Found")} -> 294 | N25: {=IFERROR(INDEX('Strategy Watchlist'!N:N,MATCH($A25,'Strategy Watchlist'!$A:$A,0)),"Not Found")} -> 45772 | O25: {=IFERROR(INDEX('Strategy Watchlist'!P:P,MATCH($A25,'Strategy Watchlist'!$A:$A,0)),"Not Found")} -> -0.88 | P25: {=IFERROR(INDEX('Strategy Watchlist'!Q:Q,MATCH($A25,'Strategy Watchlist'!$A:$A,0)),"Not Found")} -> 0.46 | Q25: {=IFERROR(INDEX('Strategy Watchlist'!R:R,MATCH($A25,'Strategy Watchlist'!$A:$A,0)),"Not Found")} -> -0.54 | R25: {=IFERROR(INDEX('Strategy Watchlist'!S:S,MATCH($A25,'Strategy Watchlist'!$A:$A,0)),"Not Found")} -> 4.43 | S25: {=IFERROR(INDEX('Strategy Watchlist'!T:T,MATCH($A25,'Strategy Watchlist'!$A:$A,0)),"Not Found")} -> -0.26 | T25: {=IFERROR(INDEX('Strategy Watchlist'!U:U,MATCH($A25,'Strategy Watchlist'!$A:$A,0)),"Not Found")} -> 0.04 | U25: {=IFERROR(INDEX('Strategy Watchlist'!V:V,MATCH($A25,'Strategy Watchlist'!$A:$A,0)),"Not Found")} -> 1.27 | V25: {=IFERROR(INDEX('Strategy Watchlist'!W:W,MATCH($A25,'Strategy Watchlist'!$A:$A,0)),"Not Found")} -> 3.69 | W25: {=IFERROR(INDEX('Strategy Watchlist'!X:X,MATCH($A25,'Strategy Watchlist'!$A:$A,0)),"Not Found")} -> -0.27 | X25: {=IFERROR(INDEX('Strategy Watchlist'!Y:Y,MATCH($A25,'Strategy Watchlist'!$A:$A,0)),"Not Found")} -> 3.17 | Y25: {=IFERROR(INDEX('Strategy Watchlist'!Z:Z,MATCH($A25,'Strategy Watchlist'!$A:$A,0)),"Not Found")} -> https://www.tradingview.com/chart/9cT1VRvW/
A26: =D26&"|"&E26&"|"&F26&"|"&G26 -> |PePe|T3 Nexus|30m | B26: active | C26: =H26/$C$4 -> 0.3 | E26: PePe | F26: T3 Nexus | G26: 30m | H26: 1500 | I26: =H26*0.21 -> 315 | J26: 460 | K26: 16 | L26: {=IFERROR(INDEX('Strategy Watchlist'!L:L,MATCH($A26,'Strategy Watchlist'!$A:$A,0)),"Not Found")} -> 0.82275229 | M26: {=IFERROR(INDEX('Strategy Watchlist'!M:M,MATCH($A26,'Strategy Watchlist'!$A:$A,0)),"Not Found")} -> 748 | N26: {=IFERROR(INDEX('Strategy Watchlist'!N:N,MATCH($A26,'Strategy Watchlist'!$A:$A,0)),"Not Found")} -> 45662 | O26: {=IFERROR(INDEX('Strategy Watchlist'!P:P,MATCH($A26,'Strategy Watchlist'!$A:$A,0)),"Not Found")} -> -8.96 | P26: {=IFERROR(INDEX('Strategy Watchlist'!Q:Q,MATCH($A26,'Strategy Watchlist'!$A:$A,0)),"Not Found")} -> -0.19 | Q26: {=IFERROR(INDEX('Strategy Watchlist'!R:R,MATCH($A26,'Strategy Watchlist'!$A:$A,0)),"Not Found")} -> 6.1 | R26: {=IFERROR(INDEX('Strategy Watchlist'!S:S,MATCH($A26,'Strategy Watchlist'!$A:$A,0)),"Not Found")} -> 3.29 | S26: {=IFERROR(INDEX('Strategy Watchlist'!T:T,MATCH($A26,'Strategy Watchlist'!$A:$A,0)),"Not Found")} -> 1.47 | T26: {=IFERROR(INDEX('Strategy Watchlist'!U:U,MATCH($A26,'Strategy Watchlist'!$A:$A,0)),"Not Found")} -> 6.2 | U26: {=IFERROR(INDEX('Strategy Watchlist'!V:V,MATCH($A26,'Strategy Watchlist'!$A:$A,0)),"Not Found")} -> -4.5 | V26: {=IFERROR(INDEX('Strategy Watchlist'!W:W,MATCH($A26,'Strategy Watchlist'!$A:$A,0)),"Not Found")} -> 4.74 | W26: {=IFERROR(INDEX('Strategy Watchlist'!X:X,MATCH($A26,'Strategy Watchlist'!$A:$A,0)),"Not Found")} -> 1.16 | X26: {=IFERROR(INDEX('Strategy Watchlist'!Y:Y,MATCH($A26,'Strategy Watchlist'!$A:$A,0)),"Not Found")} -> 7.62 | Y26: {=IFERROR(INDEX('Strategy Watchlist'!Z:Z,MATCH($A26,'Strategy Watchlist'!$A:$A,0)),"Not Found")} -> https://www.tradingview.com/chart/Kj5ZGHdw/
A27: =D27&"|"&E27&"|"&F27&"|"&G27 -> [1e052093]|SOL|FlashProfit|59m | B27: active | C27: =H27/$C$4 -> 0.8 | D27: [1e052093] | E27: SOL | F27: FlashProfit | G27: 59m | H27: 4000 | I27: =H27*0.21 -> 840 | J27: 800 | K27: 25 | L27: {=IFERROR(INDEX('Strategy Watchlist'!L:L,MATCH($A27,'Strategy Watchlist'!$A:$A,0)),"Not Found")} -> 4.1988506 | M27: {=IFERROR(INDEX('Strategy Watchlist'!M:M,MATCH($A27,'Strategy Watchlist'!$A:$A,0)),"Not Found")} -> 567 | N27: {=IFERROR(INDEX('Strategy Watchlist'!N:N,MATCH($A27,'Strategy Watchlist'!$A:$A,0)),"Not Found")} -> 45925 | O27: {=IFERROR(INDEX('Strategy Watchlist'!P:P,MATCH($A27,'Strategy Watchlist'!$A:$A,0)),"Not Found")} -> 0.82 | P27: {=IFERROR(INDEX('Strategy Watchlist'!Q:Q,MATCH($A27,'Strategy Watchlist'!$A:$A,0)),"Not Found")} -> 6.44 | Q27: {=IFERROR(INDEX('Strategy Watchlist'!R:R,MATCH($A27,'Strategy Watchlist'!$A:$A,0)),"Not Found")} -> 4.43 | R27: {=IFERROR(INDEX('Strategy Watchlist'!S:S,MATCH($A27,'Strategy Watchlist'!$A:$A,0)),"Not Found")} -> -0.32 | S27: {=IFERROR(INDEX('Strategy Watchlist'!T:T,MATCH($A27,'Strategy Watchlist'!$A:$A,0)),"Not Found")} -> 0.78 | T27: {=IFERROR(INDEX('Strategy Watchlist'!U:U,MATCH($A27,'Strategy Watchlist'!$A:$A,0)),"Not Found")} -> 2.03 | U27: {=IFERROR(INDEX('Strategy Watchlist'!V:V,MATCH($A27,'Strategy Watchlist'!$A:$A,0)),"Not Found")} -> 0.72 | V27: {=IFERROR(INDEX('Strategy Watchlist'!W:W,MATCH($A27,'Strategy Watchlist'!$A:$A,0)),"Not Found")} -> 2.39 | W27: {=IFERROR(INDEX('Strategy Watchlist'!X:X,MATCH($A27,'Strategy Watchlist'!$A:$A,0)),"Not Found")} -> 1.96 | X27: {=IFERROR(INDEX('Strategy Watchlist'!Y:Y,MATCH($A27,'Strategy Watchlist'!$A:$A,0)),"Not Found")} -> 0.45 | Y27: {=IFERROR(INDEX('Strategy Watchlist'!Z:Z,MATCH($A27,'Strategy Watchlist'!$A:$A,0)),"Not Found")} -> https://www.tradingview.com/chart/mnGjsgoY/
A28: =D28&"|"&E28&"|"&F28&"|"&G28 -> |LINK|McGinley|45m | B28: active | C28: =H28/$C$4 -> 0.7 | E28: LINK | F28: McGinley | G28: 45m | H28: 3500 | I28: =H28*0.21 -> 735 | J28: 800 | K28: 25 | L28: {=IFERROR(INDEX('Strategy Watchlist'!L:L,MATCH($A28,'Strategy Watchlist'!$A:$A,0)),"Not Found")} -> 7.7349823 | M28: {=IFERROR(INDEX('Strategy Watchlist'!M:M,MATCH($A28,'Strategy Watchlist'!$A:$A,0)),"Not Found")} -> 147 | N28: {=IFERROR(INDEX('Strategy Watchlist'!N:N,MATCH($A28,'Strategy Watchlist'!$A:$A,0)),"Not Found")} -> 45802 | O28: {=IFERROR(INDEX('Strategy Watchlist'!P:P,MATCH($A28,'Strategy Watchlist'!$A:$A,0)),"Not Found")} -> -0.55 | P28: {=IFERROR(INDEX('Strategy Watchlist'!Q:Q,MATCH($A28,'Strategy Watchlist'!$A:$A,0)),"Not Found")} -> -1.1 | Q28: {=IFERROR(INDEX('Strategy Watchlist'!R:R,MATCH($A28,'Strategy Watchlist'!$A:$A,0)),"Not Found")} -> 2.98 | R28: {=IFERROR(INDEX('Strategy Watchlist'!S:S,MATCH($A28,'Strategy Watchlist'!$A:$A,0)),"Not Found")} -> 2.97 | S28: {=IFERROR(INDEX('Strategy Watchlist'!T:T,MATCH($A28,'Strategy Watchlist'!$A:$A,0)),"Not Found")} -> 2.9 | T28: {=IFERROR(INDEX('Strategy Watchlist'!U:U,MATCH($A28,'Strategy Watchlist'!$A:$A,0)),"Not Found")} -> 2 | U28: {=IFERROR(INDEX('Strategy Watchlist'!V:V,MATCH($A28,'Strategy Watchlist'!$A:$A,0)),"Not Found")} -> 2.24 | V28: {=IFERROR(INDEX('Strategy Watchlist'!W:W,MATCH($A28,'Strategy Watchlist'!$A:$A,0)),"Not Found")} -> 0.79 | W28: {=IFERROR(INDEX('Strategy Watchlist'!X:X,MATCH($A28,'Strategy Watchlist'!$A:$A,0)),"Not Found")} -> 0.69 | X28: {=IFERROR(INDEX('Strategy Watchlist'!Y:Y,MATCH($A28,'Strategy Watchlist'!$A:$A,0)),"Not Found")} -> -0.61 | Y28: {=IFERROR(INDEX('Strategy Watchlist'!Z:Z,MATCH($A28,'Strategy Watchlist'!$A:$A,0)),"Not Found")} -> https://www.tradingview.com/chart/elrmSYee/
A29: =D29&"|"&E29&"|"&F29&"|"&G29 -> [6dcd4dc9]|ETH|precisionTrend|30m | B29: active | C29: =H29/$C$4 -> 0.6 | D29: [6dcd4dc9] | E29: ETH | F29: precisionTrend | G29: 30m | H29: 3000 | I29: =H29*0.21 -> 630 | J29: 920 | K29: 22 | L29: {=IFERROR(INDEX('Strategy Watchlist'!L:L,MATCH($A29,'Strategy Watchlist'!$A:$A,0)),"Not Found")} -> 9.211236 | M29: {=IFERROR(INDEX('Strategy Watchlist'!M:M,MATCH($A29,'Strategy Watchlist'!$A:$A,0)),"Not Found")} -> 312 | N29: {=IFERROR(INDEX('Strategy Watchlist'!N:N,MATCH($A29,'Strategy Watchlist'!$A:$A,0)),"Not Found")} -> 45772 | O29: {=IFERROR(INDEX('Strategy Watchlist'!P:P,MATCH($A29,'Strategy Watchlist'!$A:$A,0)),"Not Found")} -> 1.07 | P29: {=IFERROR(INDEX('Strategy Watchlist'!Q:Q,MATCH($A29,'Strategy Watchlist'!$A:$A,0)),"Not Found")} -> -2.52 | Q29: {=IFERROR(INDEX('Strategy Watchlist'!R:R,MATCH($A29,'Strategy Watchlist'!$A:$A,0)),"Not Found")} -> 1.84 | R29: {=IFERROR(INDEX('Strategy Watchlist'!S:S,MATCH($A29,'Strategy Watchlist'!$A:$A,0)),"Not Found")} -> 3.9 | S29: {=IFERROR(INDEX('Strategy Watchlist'!T:T,MATCH($A29,'Strategy Watchlist'!$A:$A,0)),"Not Found")} -> 1.37 | T29: {=IFERROR(INDEX('Strategy Watchlist'!U:U,MATCH($A29,'Strategy Watchlist'!$A:$A,0)),"Not Found")} -> 6.22 | U29: {=IFERROR(INDEX('Strategy Watchlist'!V:V,MATCH($A29,'Strategy Watchlist'!$A:$A,0)),"Not Found")} -> 3 | V29: {=IFERROR(INDEX('Strategy Watchlist'!W:W,MATCH($A29,'Strategy Watchlist'!$A:$A,0)),"Not Found")} -> 3.99 | W29: {=IFERROR(INDEX('Strategy Watchlist'!X:X,MATCH($A29,'Strategy Watchlist'!$A:$A,0)),"Not Found")} -> 0.93 | X29: {=IFERROR(INDEX('Strategy Watchlist'!Y:Y,MATCH($A29,'Strategy Watchlist'!$A:$A,0)),"Not Found")} -> 2.21 | Y29: {=IFERROR(INDEX('Strategy Watchlist'!Z:Z,MATCH($A29,'Strategy Watchlist'!$A:$A,0)),"Not Found")} -> https://www.tradingview.com/chart/YxD2lfI2/
A30: =D30&"|"&E30&"|"&F30&"|"&G30 -> [da58bf67]|NEAR|Trendhoo|30m | B30: active | C30: =H30/$C$4 -> 0.36 | D30: [da58bf67] | E30: NEAR | F30: Trendhoo | G30: 30m | H30: 1800 | I30: =H30*0.21 -> 378 | J30: 400 | K30: 18 | L30: {=IFERROR(INDEX('Strategy Watchlist'!L:L,MATCH($A30,'Strategy Watchlist'!$A:$A,0)),"Not Found")} -> 5.9785235 | M30: {=IFERROR(INDEX('Strategy Watchlist'!M:M,MATCH($A30,'Strategy Watchlist'!$A:$A,0)),"Not Found")} -> 188 | N30: {=IFERROR(INDEX('Strategy Watchlist'!N:N,MATCH($A30,'Strategy Watchlist'!$A:$A,0)),"Not Found")} -> 45802 | O30: {=IFERROR(INDEX('Strategy Watchlist'!P:P,MATCH($A30,'Strategy Watchlist'!$A:$A,0)),"Not Found")} -> 0.27 | P30: {=IFERROR(INDEX('Strategy Watchlist'!Q:Q,MATCH($A30,'Strategy Watchlist'!$A:$A,0)),"Not Found")} -> 0 | Q30: {=IFERROR(INDEX('Strategy Watchlist'!R:R,MATCH($A30,'Strategy Watchlist'!$A:$A,0)),"Not Found")} -> 4.76 | R30: {=IFERROR(INDEX('Strategy Watchlist'!S:S,MATCH($A30,'Strategy Watchlist'!$A:$A,0)),"Not Found")} -> 1.93 | S30: {=IFERROR(INDEX('Strategy Watchlist'!T:T,MATCH($A30,'Strategy Watchlist'!$A:$A,0)),"Not Found")} -> 1.34 | T30: {=IFERROR(INDEX('Strategy Watchlist'!U:U,MATCH($A30,'Strategy Watchlist'!$A:$A,0)),"Not Found")} -> 2.3 | U30: {=IFERROR(INDEX('Strategy Watchlist'!V:V,MATCH($A30,'Strategy Watchlist'!$A:$A,0)),"Not Found")} -> 0.08 | V30: {=IFERROR(INDEX('Strategy Watchlist'!W:W,MATCH($A30,'Strategy Watchlist'!$A:$A,0)),"Not Found")} -> 1.26 | W30: {=IFERROR(INDEX('Strategy Watchlist'!X:X,MATCH($A30,'Strategy Watchlist'!$A:$A,0)),"Not Found")} -> 1.01 | X30: {=IFERROR(INDEX('Strategy Watchlist'!Y:Y,MATCH($A30,'Strategy Watchlist'!$A:$A,0)),"Not Found")} -> 5.82 | Y30: {=IFERROR(INDEX('Strategy Watchlist'!Z:Z,MATCH($A30,'Strategy Watchlist'!$A:$A,0)),"Not Found")} -> https://www.tradingview.com/chart/CsNPJ40O/ | AU30: toWatch | AW30: NEAR | AX30: Trendhoo | AY30: =44.54/7.45 -> 5.9785235 | AZ30: 188 | BA30: 30m | BB30: 45802 | BC30: -0.16 | BD30: 4.76 | BE30: 1.93 | BF30: 1.34 | BG30: 2.3 | BH30: 0.08 | BI30: 1.26 | BJ30: 1.01 | BK30: 5.82 | BL30: [da58bf67] | BM30: https://daviddtech.com/strategy/fishyink-stiffsurge-nearusdt-1h-03-12-2024-copy/
A31: =D31&"|"&E31&"|"&F31&"|"&G31 -> [4a2ddf14]|AAVE|McGlinley|45m | B31: active | C31: =H31/$C$4 -> 0.8 | D31: [4a2ddf14] | E31: AAVE | F31: McGlinley | G31: 45m | H31: 4000 | I31: =H31*0.21 -> 840 | J31: =I31 -> 840 | K31: 23 | L31: =12.6/4.72 -> 2.6694915 | M31: 317 | N31: 45682 | O31: {=IFERROR(INDEX('Strategy Watchlist'!P:P,MATCH($A31,'Strategy Watchlist'!$A:$A,0)),"Not Found")} -> 2.66 | P31: {=IFERROR(INDEX('Strategy Watchlist'!Q:Q,MATCH($A31,'Strategy Watchlist'!$A:$A,0)),"Not Found")} -> -0.85 | Q31: {=IFERROR(INDEX('Strategy Watchlist'!R:R,MATCH($A31,'Strategy Watchlist'!$A:$A,0)),"Not Found")} -> 3.55 | R31: {=IFERROR(INDEX('Strategy Watchlist'!S:S,MATCH($A31,'Strategy Watchlist'!$A:$A,0)),"Not Found")} -> 1.77 | S31: {=IFERROR(INDEX('Strategy Watchlist'!T:T,MATCH($A31,'Strategy Watchlist'!$A:$A,0)),"Not Found")} -> 1.63 | T31: {=IFERROR(INDEX('Strategy Watchlist'!U:U,MATCH($A31,'Strategy Watchlist'!$A:$A,0)),"Not Found")} -> -1.84 | U31: {=IFERROR(INDEX('Strategy Watchlist'!V:V,MATCH($A31,'Strategy Watchlist'!$A:$A,0)),"Not Found")} -> 0.2 | V31: {=IFERROR(INDEX('Strategy Watchlist'!W:W,MATCH($A31,'Strategy Watchlist'!$A:$A,0)),"Not Found")} -> -1.49 | W31: {=IFERROR(INDEX('Strategy Watchlist'!X:X,MATCH($A31,'Strategy Watchlist'!$A:$A,0)),"Not Found")} -> 0 | X31: {=IFERROR(INDEX('Strategy Watchlist'!Y:Y,MATCH($A31,'Strategy Watchlist'!$A:$A,0)),"Not Found")} -> 0.28 | Y31: {=IFERROR(INDEX('Strategy Watchlist'!Z:Z,MATCH($A31,'Strategy Watchlist'!$A:$A,0)),"Not Found")} -> https://www.tradingview.com/chart/Xt8Libni/ | AU31: =AX31&"|"&AY31&"|"&AZ31&"|"&BA31 -> [4a2ddf14]|AAVE|McGlinley|45m | AV31: active | AX31: [4a2ddf14] | AY31: AAVE | AZ31: McGlinley | BA31: 45m | BF31: =12.6/4.72 -> 2.6694915 | BG31: 317 | BH31: 45682 | BI31: 1.1 | BJ31: -0.85 | BK31: 3.55 | BL31: 1.77 | BM31: 1.63 | BN31: -1.84 | BO31: 0.2 | BP31: -1.49 | BQ31: 0 | BR31: 0.28 | BS31: https://daviddtech.com/strategy/inactive-chibuku-mcginleyv5-aaveusdt-45m-19-12-2/
A32: =D32&"|"&E32&"|"&F32&"|"&G32 -> [b39d1d6e]|PIXEL|WolfnBear|1H | B32: active | C32: =H32/$C$4 -> 0.8 | D32: [b39d1d6e] | E32: PIXEL | F32: WolfnBear | G32: 1H | H32: 4000 | I32: =H32*0.21 -> 840 | J32: =I32 -> 840 | K32: 22 | L32: {=IFERROR(INDEX('Strategy Watchlist'!L:L,MATCH($A32,'Strategy Watchlist'!$A:$A,0)),"Not Found")} -> 6.7377399 | M32: {=IFERROR(INDEX('Strategy Watchlist'!M:M,MATCH($A32,'Strategy Watchlist'!$A:$A,0)),"Not Found")} -> 124 | N32: {=IFERROR(INDEX('Strategy Watchlist'!N:N,MATCH($A32,'Strategy Watchlist'!$A:$A,0)),"Not Found")} -> 45833 | O32: {=IFERROR(INDEX('Strategy Watchlist'!P:P,MATCH($A32,'Strategy Watchlist'!$A:$A,0)),"Not Found")} -> 1.78 | P32: {=IFERROR(INDEX('Strategy Watchlist'!Q:Q,MATCH($A32,'Strategy Watchlist'!$A:$A,0)),"Not Found")} -> -0.58 | Q32: {=IFERROR(INDEX('Strategy Watchlist'!R:R,MATCH($A32,'Strategy Watchlist'!$A:$A,0)),"Not Found")} -> 2.67 | R32: {=IFERROR(INDEX('Strategy Watchlist'!S:S,MATCH($A32,'Strategy Watchlist'!$A:$A,0)),"Not Found")} -> 4.07 | S32: {=IFERROR(INDEX('Strategy Watchlist'!T:T,MATCH($A32,'Strategy Watchlist'!$A:$A,0)),"Not Found")} -> 2.3 | T32: {=IFERROR(INDEX('Strategy Watchlist'!U:U,MATCH($A32,'Strategy Watchlist'!$A:$A,0)),"Not Found")} -> 1.05 | U32: {=IFERROR(INDEX('Strategy Watchlist'!V:V,MATCH($A32,'Strategy Watchlist'!$A:$A,0)),"Not Found")} -> -1.13 | V32: {=IFERROR(INDEX('Strategy Watchlist'!W:W,MATCH($A32,'Strategy Watchlist'!$A:$A,0)),"Not Found")} -> 0.64 | W32: {=IFERROR(INDEX('Strategy Watchlist'!X:X,MATCH($A32,'Strategy Watchlist'!$A:$A,0)),"Not Found")} -> -0.53 | X32: {=IFERROR(INDEX('Strategy Watchlist'!Y:Y,MATCH($A32,'Strategy Watchlist'!$A:$A,0)),"Not Found")} -> -0.16 | Y32: {=IFERROR(INDEX('Strategy Watchlist'!Z:Z,MATCH($A32,'Strategy Watchlist'!$A:$A,0)),"Not Found")} -> https://www.tradingview.com/chart/7HMGQSsJ/ | AU32: toWatch | AV32: d | AW32: PIXEL | AX32: WolfnBear | AY32: 8.125 | AZ32: 124 | BA32: 1H | BB32: 45833 | BC32: -0.09 | BD32: 2.89 | BE32: 4.46 | BF32: 2.52 | BG32: 1.25 | BH32: -1.13 | BI32: 0.64 | BJ32: -0.53 | BK32: -0.16 | BL32: [b39d1d6e] | BM32: https://daviddtech.com/strategy/reid-wolfbearv5-pixelusdt-1h-14-01-2025-copy/
A33: =D33&"|"&E33&"|"&F33&"|"&G33 -> [8a00ecfa]|ADA|JpTrendForce|1H | B33: active | C33: =H33/$C$4 -> 0.4 | D33: [8a00ecfa] | E33: ADA | F33: JpTrendForce | G33: 1H | H33: 2000 | I33: =H33*0.21 -> 420 | J33: =I33 -> 420 | K33: 25 | L33: =38.28/5.19 -> 7.3757225 | M33: 160 | N33: 45682 | O33: {=IFERROR(INDEX('Strategy Watchlist'!P:P,MATCH($A33,'Strategy Watchlist'!$A:$A,0)),"Not Found")} -> 3.77 | P33: -1.61 | Q33: 1.35 | R33: 2.58 | S33: 3.16 | T33: 1.52 | U33: -1.1 | V33: -1.24 | W33: 0 | X33: 0 | Y33: https://daviddtech.com/strategy/gentlesir-jptrendforce-adausdt-1h-15-10-2024-copy/ | AU33: =AX33&"|"&AY33&"|"&AZ33&"|"&BA33 -> [8a00ecfa]|ADA|JpTrendForce|1H | AV33: toWatch | AX33: [8a00ecfa] | AY33: ADA | AZ33: JpTrendForce | BA33: 1H | BF33: =38.28/5.19 -> 7.3757225 | BG33: 160 | BH33: 45682 | BI33: 3.77 | BJ33: -1.61 | BK33: 1.35 | BL33: 2.58 | BM33: 3.16 | BN33: 1.52 | BO33: -1.1 | BP33: -1.24 | BQ33: 0 | BR33: 0 | BS33: https://daviddtech.com/strategy/gentlesir-jptrendforce-adausdt-1h-15-10-2024-copy/
A34: =D34&"|"&E34&"|"&F34&"|"&G34 -> [fbf06b43]|MNT|Trendhoo|37m | B34: active | C34: =H34/$C$4 -> 0.7 | D34: [fbf06b43] | E34: MNT | F34: Trendhoo | G34: 37m | H34: 3500 | I34: =H34*0.21 -> 735 | J34: =I34 -> 735 | K34: 28 | L34: =106.85/16.15 -> 6.6160991 | M34: 846 | N34: 45863 | O34: {=IFERROR(INDEX('Strategy Watchlist'!P:P,MATCH($A34,'Strategy Watchlist'!$A:$A,0)),"Not Found")} -> 2.49 | P34: 6.22 | Q34: 2.4 | R34: 14.95 | S34: -0.75 | T34: 2.18 | U34: -6.96 | V34: -0.73 | W34: -1.92 | X34: 6.73 | Y34: https://daviddtech.com/strategy/creedomrings-trendhoo-mntusdt-37m-06-08-copy/ | AU34: =AX34&"|"&AY34&"|"&AZ34&"|"&BA34 -> [fbf06b43]|MNT|Trendhoo|37m | AV34: active | AW34: 0.2 | AX34: [fbf06b43] | AY34: MNT | AZ34: Trendhoo | BA34: 37m | BF34: =106.85/16.15 -> 6.6160991 | BG34: 846 | BH34: 45863 | BI34: 2.49 | BJ34: 6.22 | BK34: 2.4 | BL34: 14.95 | BM34: -0.75 | BN34: 2.18 | BO34: -6.96 | BP34: -0.73 | BQ34: -1.92 | BR34: 6.73 | BS34: https://daviddtech.com/strategy/creedomrings-trendhoo-mntusdt-37m-06-08-copy/
A36: =D36&"|"&E36&"|"&F36&"|"&G36 -> 5x|BTC|DCA|30m | B36: active | D36: 5x | E36: BTC | F36: DCA | G36: 30m | H36: 1071 | I36: 5 | J36: =H36*I36 -> 5355
A43: =D43&"|"&E43&"|"&F43&"|"&G43 -> |25000|36000| | B43: Dexigner/MyBybit | E43: 25000 | F43: 36000
A44: =D44&"|"&E44&"|"&F44&"|"&G44 -> [17ab2738]|ARB|stiff Surge|45m | B44: active | C44: =H44/$F$43 -> 0.55555556 | D44: [17ab2738] | E44: ARB | F44: stiff Surge | G44: 45m | H44: 20000 | I44: =H44*0.21 -> 4200 | J44: 5400 | K44: 200 | L44: {=IFERROR(INDEX('Strategy Watchlist'!L:L,MATCH($A44,'Strategy Watchlist'!$A:$A,0)),"Not Found")} -> 10.965644 | M44: {=IFERROR(INDEX('Strategy Watchlist'!M:M,MATCH($A44,'Strategy Watchlist'!$A:$A,0)),"Not Found")} -> 824 | N44: {=IFERROR(INDEX('Strategy Watchlist'!N:N,MATCH($A44,'Strategy Watchlist'!$A:$A,0)),"Not Found")} -> 45689 | O44: {=IFERROR(INDEX('Strategy Watchlist'!P:P,MATCH($A44,'Strategy Watchlist'!$A:$A,0)),"Not Found")} -> -1.7 | P44: {=IFERROR(INDEX('Strategy Watchlist'!Q:Q,MATCH($A44,'Strategy Watchlist'!$A:$A,0)),"Not Found")} -> -6.85 | Q44: {=IFERROR(INDEX('Strategy Watchlist'!R:R,MATCH($A44,'Strategy Watchlist'!$A:$A,0)),"Not Found")} -> 1.99 | R44: {=IFERROR(INDEX('Strategy Watchlist'!S:S,MATCH($A44,'Strategy Watchlist'!$A:$A,0)),"Not Found")} -> 6.96 | S44: {=IFERROR(INDEX('Strategy Watchlist'!T:T,MATCH($A44,'Strategy Watchlist'!$A:$A,0)),"Not Found")} -> 8.074 | T44: {=IFERROR(INDEX('Strategy Watchlist'!U:U,MATCH($A44,'Strategy Watchlist'!$A:$A,0)),"Not Found")} -> 11.5 | U44: {=IFERROR(INDEX('Strategy Watchlist'!V:V,MATCH($A44,'Strategy Watchlist'!$A:$A,0)),"Not Found")} -> 2.75 | V44: {=IFERROR(INDEX('Strategy Watchlist'!W:W,MATCH($A44,'Strategy Watchlist'!$A:$A,0)),"Not Found")} -> 2.57 | W44: {=IFERROR(INDEX('Strategy Watchlist'!X:X,MATCH($A44,'Strategy Watchlist'!$A:$A,0)),"Not Found")} -> 6.31 | X44: {=IFERROR(INDEX('Strategy Watchlist'!Y:Y,MATCH($A44,'Strategy Watchlist'!$A:$A,0)),"Not Found")} -> 7.91 | Y44: {=IFERROR(INDEX('Strategy Watchlist'!Z:Z,MATCH($A44,'Strategy Watchlist'!$A:$A,0)),"Not Found")} -> https://www.tradingview.com/chart/EjQUtmuc/
A45: =D45&"|"&E45&"|"&F45&"|"&G45 -> |DOGE|MACD|45m | B45: active | C45: =H45/$F$43 -> 0.33333333 | E45: DOGE | F45: MACD | G45: 45m | H45: 12000 | I45: =H45*0.21 -> 2520 | J45: 4900 | K45: 180 | L45: {=IFERROR(INDEX('Strategy Watchlist'!L:L,MATCH($A45,'Strategy Watchlist'!$A:$A,0)),"Not Found")} -> 6.8331771 | M45: {=IFERROR(INDEX('Strategy Watchlist'!M:M,MATCH($A45,'Strategy Watchlist'!$A:$A,0)),"Not Found")} -> 147 | N45: {=IFERROR(INDEX('Strategy Watchlist'!N:N,MATCH($A45,'Strategy Watchlist'!$A:$A,0)),"Not Found")} -> 45662 | O45: {=IFERROR(INDEX('Strategy Watchlist'!P:P,MATCH($A45,'Strategy Watchlist'!$A:$A,0)),"Not Found")} -> -3.88 | P45: {=IFERROR(INDEX('Strategy Watchlist'!Q:Q,MATCH($A45,'Strategy Watchlist'!$A:$A,0)),"Not Found")} -> 5.91 | Q45: {=IFERROR(INDEX('Strategy Watchlist'!R:R,MATCH($A45,'Strategy Watchlist'!$A:$A,0)),"Not Found")} -> -0.08 | R45: {=IFERROR(INDEX('Strategy Watchlist'!S:S,MATCH($A45,'Strategy Watchlist'!$A:$A,0)),"Not Found")} -> 4.72 | S45: {=IFERROR(INDEX('Strategy Watchlist'!T:T,MATCH($A45,'Strategy Watchlist'!$A:$A,0)),"Not Found")} -> 8.93 | T45: {=IFERROR(INDEX('Strategy Watchlist'!U:U,MATCH($A45,'Strategy Watchlist'!$A:$A,0)),"Not Found")} -> 2.69 | U45: {=IFERROR(INDEX('Strategy Watchlist'!V:V,MATCH($A45,'Strategy Watchlist'!$A:$A,0)),"Not Found")} -> 2.04 | V45: {=IFERROR(INDEX('Strategy Watchlist'!W:W,MATCH($A45,'Strategy Watchlist'!$A:$A,0)),"Not Found")} -> 5.31 | W45: {=IFERROR(INDEX('Strategy Watchlist'!X:X,MATCH($A45,'Strategy Watchlist'!$A:$A,0)),"Not Found")} -> 0.72 | X45: {=IFERROR(INDEX('Strategy Watchlist'!Y:Y,MATCH($A45,'Strategy Watchlist'!$A:$A,0)),"Not Found")} -> 3.27 | Y45: {=IFERROR(INDEX('Strategy Watchlist'!Z:Z,MATCH($A45,'Strategy Watchlist'!$A:$A,0)),"Not Found")} -> https://www.tradingview.com/chart/Dvd9vGt5/
A46: =D46&"|"&E46&"|"&F46&"|"&G46 -> [a9aeb4cc]|ETH|McGinley|90m | B46: active | C46: =H46/$F$43 -> 0.41666667 | D46: [a9aeb4cc] | E46: ETH | F46: McGinley | G46: 90m | H46: 15000 | I46: =H46*0.21 -> 3150 | J46: 6030 | K46: 150 | L46: {=IFERROR(INDEX('Strategy Watchlist'!L:L,MATCH($A46,'Strategy Watchlist'!$A:$A,0)),"Not Found")} -> 7.4173228 | M46: {=IFERROR(INDEX('Strategy Watchlist'!M:M,MATCH($A46,'Strategy Watchlist'!$A:$A,0)),"Not Found")} -> 72 | N46: {=IFERROR(INDEX('Strategy Watchlist'!N:N,MATCH($A46,'Strategy Watchlist'!$A:$A,0)),"Not Found")} -> 45772 | O46: {=IFERROR(INDEX('Strategy Watchlist'!P:P,MATCH($A46,'Strategy Watchlist'!$A:$A,0)),"Not Found")} -> -0.43 | P46: {=IFERROR(INDEX('Strategy Watchlist'!Q:Q,MATCH($A46,'Strategy Watchlist'!$A:$A,0)),"Not Found")} -> -0.39 | Q46: {=IFERROR(INDEX('Strategy Watchlist'!R:R,MATCH($A46,'Strategy Watchlist'!$A:$A,0)),"Not Found")} -> 2.45 | R46: {=IFERROR(INDEX('Strategy Watchlist'!S:S,MATCH($A46,'Strategy Watchlist'!$A:$A,0)),"Not Found")} -> -0.24 | S46: {=IFERROR(INDEX('Strategy Watchlist'!T:T,MATCH($A46,'Strategy Watchlist'!$A:$A,0)),"Not Found")} -> 0.53 | T46: {=IFERROR(INDEX('Strategy Watchlist'!U:U,MATCH($A46,'Strategy Watchlist'!$A:$A,0)),"Not Found")} -> 2.38 | U46: {=IFERROR(INDEX('Strategy Watchlist'!V:V,MATCH($A46,'Strategy Watchlist'!$A:$A,0)),"Not Found")} -> 0.94 | V46: {=IFERROR(INDEX('Strategy Watchlist'!W:W,MATCH($A46,'Strategy Watchlist'!$A:$A,0)),"Not Found")} -> 0 | W46: {=IFERROR(INDEX('Strategy Watchlist'!X:X,MATCH($A46,'Strategy Watchlist'!$A:$A,0)),"Not Found")} -> 2.77 | X46: {=IFERROR(INDEX('Strategy Watchlist'!Y:Y,MATCH($A46,'Strategy Watchlist'!$A:$A,0)),"Not Found")} -> -0.13 | Y46: {=IFERROR(INDEX('Strategy Watchlist'!Z:Z,MATCH($A46,'Strategy Watchlist'!$A:$A,0)),"Not Found")} -> https://www.tradingview.com/chart/dPRT8fSK/
A47: =D47&"|"&E47&"|"&F47&"|"&G47 -> [f80d2657]|PePe|JP Trend|30m | B47: active | C47: =H47/$F$43 -> 0.41666667 | D47: [f80d2657] | E47: PePe | F47: JP Trend | G47: 30m | H47: 15000 | I47: =H47*0.21 -> 3150 | J47: 3380 | K47: 150 | L47: {=IFERROR(INDEX('Strategy Watchlist'!L:L,MATCH($A47,'Strategy Watchlist'!$A:$A,0)),"Not Found")} -> 11.341646 | M47: {=IFERROR(INDEX('Strategy Watchlist'!M:M,MATCH($A47,'Strategy Watchlist'!$A:$A,0)),"Not Found")} -> 302 | N47: {=IFERROR(INDEX('Strategy Watchlist'!N:N,MATCH($A47,'Strategy Watchlist'!$A:$A,0)),"Not Found")} -> 45662 | O47: {=IFERROR(INDEX('Strategy Watchlist'!P:P,MATCH($A47,'Strategy Watchlist'!$A:$A,0)),"Not Found")} -> 3.05 | P47: {=IFERROR(INDEX('Strategy Watchlist'!Q:Q,MATCH($A47,'Strategy Watchlist'!$A:$A,0)),"Not Found")} -> 1.52 | Q47: {=IFERROR(INDEX('Strategy Watchlist'!R:R,MATCH($A47,'Strategy Watchlist'!$A:$A,0)),"Not Found")} -> -3.15 | R47: {=IFERROR(INDEX('Strategy Watchlist'!S:S,MATCH($A47,'Strategy Watchlist'!$A:$A,0)),"Not Found")} -> 2.3 | S47: {=IFERROR(INDEX('Strategy Watchlist'!T:T,MATCH($A47,'Strategy Watchlist'!$A:$A,0)),"Not Found")} -> -0.12 | T47: {=IFERROR(INDEX('Strategy Watchlist'!U:U,MATCH($A47,'Strategy Watchlist'!$A:$A,0)),"Not Found")} -> 5.69 | U47: {=IFERROR(INDEX('Strategy Watchlist'!V:V,MATCH($A47,'Strategy Watchlist'!$A:$A,0)),"Not Found")} -> -1.33 | V47: {=IFERROR(INDEX('Strategy Watchlist'!W:W,MATCH($A47,'Strategy Watchlist'!$A:$A,0)),"Not Found")} -> 2.12 | W47: {=IFERROR(INDEX('Strategy Watchlist'!X:X,MATCH($A47,'Strategy Watchlist'!$A:$A,0)),"Not Found")} -> 3.07 | X47: {=IFERROR(INDEX('Strategy Watchlist'!Y:Y,MATCH($A47,'Strategy Watchlist'!$A:$A,0)),"Not Found")} -> 3.75 | Y47: {=IFERROR(INDEX('Strategy Watchlist'!Z:Z,MATCH($A47,'Strategy Watchlist'!$A:$A,0)),"Not Found")} -> https://www.tradingview.com/chart/uNPZ2spK/
A48: =D48&"|"&E48&"|"&F48&"|"&G48 -> |LINK|McGinley|45m | B48: active | C48: =H48/$F$43 -> 0.5 | E48: LINK | F48: McGinley | G48: 45m | H48: 18000 | I48: =H48*0.21 -> 3780 | J48: 4000 | K48: 160 | L48: {=IFERROR(INDEX('Strategy Watchlist'!L:L,MATCH($A48,'Strategy Watchlist'!$A:$A,0)),"Not Found")} -> 7.7349823 | M48: {=IFERROR(INDEX('Strategy Watchlist'!M:M,MATCH($A48,'Strategy Watchlist'!$A:$A,0)),"Not Found")} -> 147 | N48: {=IFERROR(INDEX('Strategy Watchlist'!N:N,MATCH($A48,'Strategy Watchlist'!$A:$A,0)),"Not Found")} -> 45802 | O48: {=IFERROR(INDEX('Strategy Watchlist'!P:P,MATCH($A48,'Strategy Watchlist'!$A:$A,0)),"Not Found")} -> -0.55 | P48: {=IFERROR(INDEX('Strategy Watchlist'!Q:Q,MATCH($A48,'Strategy Watchlist'!$A:$A,0)),"Not Found")} -> -1.1 | Q48: {=IFERROR(INDEX('Strategy Watchlist'!R:R,MATCH($A48,'Strategy Watchlist'!$A:$A,0)),"Not Found")} -> 2.98 | R48: {=IFERROR(INDEX('Strategy Watchlist'!S:S,MATCH($A48,'Strategy Watchlist'!$A:$A,0)),"Not Found")} -> 2.97 | S48: {=IFERROR(INDEX('Strategy Watchlist'!T:T,MATCH($A48,'Strategy Watchlist'!$A:$A,0)),"Not Found")} -> 2.9 | T48: {=IFERROR(INDEX('Strategy Watchlist'!U:U,MATCH($A48,'Strategy Watchlist'!$A:$A,0)),"Not Found")} -> 2 | U48: {=IFERROR(INDEX('Strategy Watchlist'!V:V,MATCH($A48,'Strategy Watchlist'!$A:$A,0)),"Not Found")} -> 2.24 | V48: {=IFERROR(INDEX('Strategy Watchlist'!W:W,MATCH($A48,'Strategy Watchlist'!$A:$A,0)),"Not Found")} -> 0.79 | W48: {=IFERROR(INDEX('Strategy Watchlist'!X:X,MATCH($A48,'Strategy Watchlist'!$A:$A,0)),"Not Found")} -> 0.69 | X48: {=IFERROR(INDEX('Strategy Watchlist'!Y:Y,MATCH($A48,'Strategy Watchlist'!$A:$A,0)),"Not Found")} -> -0.61 | Y48: {=IFERROR(INDEX('Strategy Watchlist'!Z:Z,MATCH($A48,'Strategy Watchlist'!$A:$A,0)),"Not Found")} -> https://www.tradingview.com/chart/elrmSYee/
A49: =D49&"|"&E49&"|"&F49&"|"&G49 -> [e92283ec]|HBAR|Heiken-Ashi|30m | B49: active | C49: =H49/$F$43 -> 0.44444444 | D49: [e92283ec] | E49: HBAR | F49: Heiken-Ashi | G49: 30m | H49: 16000 | I49: =H49*0.21 -> 3360 | J49: 5320 | K49: 180 | L49: {=IFERROR(INDEX('Strategy Watchlist'!L:L,MATCH($A49,'Strategy Watchlist'!$A:$A,0)),"Not Found")} -> 6.7744 | M49: {=IFERROR(INDEX('Strategy Watchlist'!M:M,MATCH($A49,'Strategy Watchlist'!$A:$A,0)),"Not Found")} -> 224 | N49: {=IFERROR(INDEX('Strategy Watchlist'!N:N,MATCH($A49,'Strategy Watchlist'!$A:$A,0)),"Not Found")} -> 45833 | O49: {=IFERROR(INDEX('Strategy Watchlist'!P:P,MATCH($A49,'Strategy Watchlist'!$A:$A,0)),"Not Found")} -> 1.01 | P49: {=IFERROR(INDEX('Strategy Watchlist'!Q:Q,MATCH($A49,'Strategy Watchlist'!$A:$A,0)),"Not Found")} -> -1.15 | Q49: {=IFERROR(INDEX('Strategy Watchlist'!R:R,MATCH($A49,'Strategy Watchlist'!$A:$A,0)),"Not Found")} -> 0.83 | R49: {=IFERROR(INDEX('Strategy Watchlist'!S:S,MATCH($A49,'Strategy Watchlist'!$A:$A,0)),"Not Found")} -> 1.52 | S49: {=IFERROR(INDEX('Strategy Watchlist'!T:T,MATCH($A49,'Strategy Watchlist'!$A:$A,0)),"Not Found")} -> -0.03 | T49: {=IFERROR(INDEX('Strategy Watchlist'!U:U,MATCH($A49,'Strategy Watchlist'!$A:$A,0)),"Not Found")} -> 4.38 | U49: {=IFERROR(INDEX('Strategy Watchlist'!V:V,MATCH($A49,'Strategy Watchlist'!$A:$A,0)),"Not Found")} -> 1.95 | V49: {=IFERROR(INDEX('Strategy Watchlist'!W:W,MATCH($A49,'Strategy Watchlist'!$A:$A,0)),"Not Found")} -> 1.98 | W49: {=IFERROR(INDEX('Strategy Watchlist'!X:X,MATCH($A49,'Strategy Watchlist'!$A:$A,0)),"Not Found")} -> 4.59 | X49: {=IFERROR(INDEX('Strategy Watchlist'!Y:Y,MATCH($A49,'Strategy Watchlist'!$A:$A,0)),"Not Found")} -> -1.3 | Y49: {=IFERROR(INDEX('Strategy Watchlist'!Z:Z,MATCH($A49,'Strategy Watchlist'!$A:$A,0)),"Not Found")} -> https://www.tradingview.com/chart/ygHXwF84/
A50: =D50&"|"&E50&"|"&F50&"|"&G50 -> [65caeaa0]|ROSE|WolfnBear|1H | B50: active | C50: =H50/$F$43 -> 0.55555556 | D50: [65caeaa0] | E50: ROSE | F50: WolfnBear | G50: 1H | H50: 20000 | I50: =H50*0.21 -> 4200 | J50: =I50 -> 4200 | K50: 200 | L50: {=IFERROR(INDEX('Strategy Watchlist'!L:L,MATCH($A50,'Strategy Watchlist'!$A:$A,0)),"Not Found")} -> 9.1257485 | M50: {=IFERROR(INDEX('Strategy Watchlist'!M:M,MATCH($A50,'Strategy Watchlist'!$A:$A,0)),"Not Found")} -> 172 | N50: {=IFERROR(INDEX('Strategy Watchlist'!N:N,MATCH($A50,'Strategy Watchlist'!$A:$A,0)),"Not Found")} -> 45682 | O50: {=IFERROR(INDEX('Strategy Watchlist'!P:P,MATCH($A50,'Strategy Watchlist'!$A:$A,0)),"Not Found")} -> 1.04 | P50: {=IFERROR(INDEX('Strategy Watchlist'!Q:Q,MATCH($A50,'Strategy Watchlist'!$A:$A,0)),"Not Found")} -> 2.39 | Q50: {=IFERROR(INDEX('Strategy Watchlist'!R:R,MATCH($A50,'Strategy Watchlist'!$A:$A,0)),"Not Found")} -> 0.38 | R50: {=IFERROR(INDEX('Strategy Watchlist'!S:S,MATCH($A50,'Strategy Watchlist'!$A:$A,0)),"Not Found")} -> 1.76 | S50: {=IFERROR(INDEX('Strategy Watchlist'!T:T,MATCH($A50,'Strategy Watchlist'!$A:$A,0)),"Not Found")} -> 0.72 | T50: {=IFERROR(INDEX('Strategy Watchlist'!U:U,MATCH($A50,'Strategy Watchlist'!$A:$A,0)),"Not Found")} -> -0.84 | U50: {=IFERROR(INDEX('Strategy Watchlist'!V:V,MATCH($A50,'Strategy Watchlist'!$A:$A,0)),"Not Found")} -> -0.24 | V50: {=IFERROR(INDEX('Strategy Watchlist'!W:W,MATCH($A50,'Strategy Watchlist'!$A:$A,0)),"Not Found")} -> -1.19 | W50: {=IFERROR(INDEX('Strategy Watchlist'!X:X,MATCH($A50,'Strategy Watchlist'!$A:$A,0)),"Not Found")} -> 0.18 | X50: {=IFERROR(INDEX('Strategy Watchlist'!Y:Y,MATCH($A50,'Strategy Watchlist'!$A:$A,0)),"Not Found")} -> 2.34 | Y50: {=IFERROR(INDEX('Strategy Watchlist'!Z:Z,MATCH($A50,'Strategy Watchlist'!$A:$A,0)),"Not Found")} -> https://www.tradingview.com/chart/p2Bvj1LX/
...

Sheet Strategy Watchlist
A2: KEY | B2: STATUS | C2: RATIO | D2: ID | E2: COIN PAIR | F2: STRATEGY | G2: TIMEFRAME | H2: Initial Capital | I2: Caculated Size | J2: Actual Size | K2: Average PnL Per Trade | L2: NP/DD | M2: Total Trades | N2: LIVE SINCE | O2: NOV | P2: OCT | Q2: SEP | R2: AUG | S2: JULY | T2: JUNE | U2: MAY | V2: APR | W2: MAR | X2: FEB | Y2: JAN | Z2: LINK
A3: =D3&"|"&E3&"|"&F3&"|"&G3 -> [17ab2738]|ARB|stiff Surge|45m | B3: active | C3: 0.5 | D3: [17ab2738] | E3: ARB | F3: stiff Surge | G3: 45m | H3: 20000 | I3: =H3*0.21 -> 4200 | J3: 7500 | K3: 200 | L3: =89.37/8.15 -> 10.965644 | M3: 824 | N3: 45689 | P3: -1.7 | Q3: -6.85 | R3: 1.99 | S3: 6.96 | T3: 8.074 | U3: 11.5 | V3: 2.75 | W3: 2.57 | X3: 6.31 | Y3: 7.91 | Z3: https://www.tradingview.com/chart/EjQUtmuc/
A4: =D4&"|"&E4&"|"&F4&"|"&G4 -> |DOGE|MACD|45m | B4: active | C4: 0.3125 | E4: DOGE | F4: MACD | G4: 45m | H4: 12500 | I4: =H4*0.21 -> 2625 | J4: 4000 | K4: 200 | L4: =72.91/10.67 -> 6.8331771 | M4: 147 | N4: 45662 | P4: -3.88 | Q4: 5.91 | R4: -0.08 | S4: 4.72 | T4: 8.93 | U4: 2.69 | V4: 2.04 | W4: 5.31 | X4: 0.72 | Y4: 3.27 | Z4: https://www.tradingview.com/chart/Dvd9vGt5/
